<?xml version="1.0" ?>
<robot xmlns:xacro="http://ros.org/wiki/xacro">
  <xacro:macro name="motoman_sia20" params="prefix">
    <link name="${prefix}base_link">
      <visual>
        <origin rpy="0 0 0" xyz="0 0 0"/>
        <geometry>
          <mesh filename="package://motoman_sia_support/meshes/sia20/visual/base_link.dae" />
        </geometry>
        <material name="white">
          <color rgba="1 1 1 1"/>
        </material>
      </visual>
      <collision>
        <origin rpy="0 0 0" xyz="0 0 0"/>
        <geometry>
          <mesh filename="package://motoman_sia_support/meshes/sia20/collision/base_link.stl" />
        </geometry>
      </collision>
    </link>
    <link name="${prefix}link_s">
      <visual>
        <origin rpy="0 0 0" xyz="0 0 0"/>
        <geometry>
          <mesh filename="package://motoman_sia_support/meshes/sia20/visual/link_s.dae"/>
        </geometry>
        <material name="blue">
          <color rgba="0 0 1 1"/>
        </material>
      </visual>
      <collision>
        <origin rpy="0 0 0" xyz="0 0 0"/>
        <geometry>
          <mesh filename="package://motoman_sia_support/meshes/sia20/collision/link_s.stl" />
        </geometry>
      </collision>
    </link>
    <link name="${prefix}link_l">
      <visual>
        <origin rpy="0 0 0" xyz="0 0 0"/>
        <geometry>
          <mesh filename="package://motoman_sia_support/meshes/sia20/visual/link_l.dae"/>
        </geometry>
        <material name="white"/>
      </visual>
      <collision>
        <origin rpy="0 0 0" xyz="0 0 0"/>
        <geometry>
          <mesh filename="package://motoman_sia_support/meshes/sia20/collision/link_l.stl"/>
        </geometry>
      </collision>
    </link>
    <link name="${prefix}link_e">
      <visual>
        <origin rpy="0 0 0" xyz="0 0 0"/>
        <geometry>
          <mesh filename="package://motoman_sia_support/meshes/sia20/visual/link_e.dae"/>
        </geometry>
        <material name="white"/>
      </visual>
      <collision>
        <origin rpy="0 0 0" xyz="0 0 0"/>
        <geometry>
          <mesh filename="package://motoman_sia_support/meshes/sia20/collision/link_e.stl"/>
        </geometry>
      </collision>
    </link>
    <link name="${prefix}link_u">
      <visual>
        <origin rpy="0 0 0" xyz="0 0 0"/>
        <geometry>
          <mesh filename="package://motoman_sia_support/meshes/sia20/visual/link_u.dae"/>
        </geometry>
        <material name="blue"/>
      </visual>
      <collision>
        <origin rpy="0 0 0" xyz="0 0 0"/>
        <geometry>
          <mesh filename="package://motoman_sia_support/meshes/sia20/collision/link_u.stl"/>
        </geometry>
      </collision>
    </link>
    <link name="${prefix}link_r">
      <visual>
        <origin rpy="0 0 0" xyz="0 0 0"/>
        <geometry>
          <mesh filename="package://motoman_sia_support/meshes/sia20/visual/link_r.dae"/>
        </geometry>
        <material name="white"/>
      </visual>
      <collision>
        <origin rpy="0 0 0" xyz="0 0 0"/>
        <geometry>
          <mesh filename="package://motoman_sia_support/meshes/sia20/collision/link_r.stl"/>
        </geometry>
      </collision>
    </link>
    <link name="${prefix}link_b">
      <visual>
        <origin rpy="0 0 0" xyz="0 0 0"/>
        <geometry>
          <mesh filename="package://motoman_sia_support/meshes/sia20/visual/link_b.dae"/>
        </geometry>
        <material name="blue"/>
      </visual>
      <collision>
        <origin rpy="0 0 0" xyz="0 0 0"/>
        <geometry>
          <mesh filename="package://motoman_sia_support/meshes/sia20/collision/link_b.stl"/>
        </geometry>
      </collision>
    </link>
    <link name="${prefix}link_t">
      <visual>
        <origin rpy="0 0 0" xyz="0 0 0"/>
        <geometry>
          <mesh filename="package://motoman_sia_support/meshes/sia20/visual/link_t.dae" />
        </geometry>
        <material name="silver">
          <color rgba="0.45 0.45 0.45 1"/>
        </material>
      </visual>
      <collision>
        <origin rpy="0 0 0" xyz="0 0 0"/>
        <geometry>
          <mesh filename="package://motoman_sia_support/meshes/sia20/collision/link_t.stl" />
        </geometry>
      </collision>
    </link>
    <link name="${prefix}tool0" />

    <joint name="${prefix}joint_s" type="revolute">
      <parent link="${prefix}base_link"/>
      <child link="${prefix}link_s"/>
      <origin xyz="0 0 0.41" rpy="0 0 0"/>
      <axis xyz="0 0 1" />
      <limit lower="-3.1416" upper="3.1416" effort="0" velocity="2.26" />
    </joint>
    <joint name="${prefix}joint_l" type="revolute">
      <parent link="${prefix}link_s"/>
      <child link="${prefix}link_l"/>
      <origin xyz="0 0 0" rpy="0 0 0"/>
      <axis xyz="0 1 0" />
      <limit lower="-1.91" upper="1.91" effort="0" velocity="2.26" />
    </joint>
    <joint name="${prefix}joint_e" type="revolute">
      <parent link="${prefix}link_l"/>
      <child link="${prefix}link_e"/>
      <origin xyz="0 0 0.49" rpy="0 0 0"/>
      <axis xyz="0 0 1" />
      <limit lower="-2.96" upper="2.96" effort="0" velocity="2.96" />
    </joint>
    <joint name="${prefix}joint_u" type="revolute">
      <parent link="${prefix}link_e"/>
      <child link="${prefix}link_u"/>
      <origin xyz="0 0 0" rpy="0 0 0"/>
      <axis xyz="0 -1 0" />
      <limit lower="-2.26" upper="2.26" effort="0" velocity="2.96" />
    </joint>
    <joint name="${prefix}joint_r" type="revolute">
      <parent link="${prefix}link_u"/>
      <child link="${prefix}link_r"/>
      <origin xyz="0 0 0.420" rpy="0 0 0"/>
      <axis xyz="0 0 -1" />
      <limit lower="-3.1416" upper="3.1416" effort="0" velocity="3.48" />
    </joint>
    <joint name="${prefix}joint_b" type="revolute">
      <parent link="${prefix}link_r"/>
      <child link="${prefix}link_b"/>
      <origin xyz="0 0 0" rpy="0 0 0"/>
      <axis xyz="0 -1 0" />
      <limit lower="-1.91" upper="1.91" effort="0" velocity="3.48" />
    </joint>
    <joint name="${prefix}joint_t" type="revolute">
      <parent link="${prefix}link_b"/>
      <child link="${prefix}link_t"/>
      <origin xyz="0 0 0.18" rpy="0 0 0"/>
      <axis xyz="0 0 -1" />
      <limit lower="-3.1416" upper="3.1416" effort="0" velocity="6.97" />
    </joint>
    <joint name="${prefix}link_t-tool0" type="fixed" >
      <origin xyz="0 0 0.0" rpy="0 0 -3.1416"/>
      <parent link="${prefix}link_t" />
      <child link="${prefix}tool0" />
    </joint>
  </xacro:macro>
</robot>
